<?xml version="1.0"?>
<robot name="blocky_spider">
  <link name="body">
    <visual>
      
      <geometry><cylinder radius="0.21875" length="0.025"/></geometry>
    </visual>
    <collision>
      
      <geometry><cylinder radius="0.21875" length="0.025"/></geometry>
    </collision>
    <inertial>
      <mass value="9.019807"/>
      <inertia ixx="2.158059e-01" iyy="1.083727e-01" izz="1.083727e-01" ixy="0" ixz="0" iyz="0"/>
    </inertial>
  </link>
  <link name="leg_hip_0">
    <visual>
      <origin xyz="0.0125 0 0" rpy="0 0 0"/>
      <geometry><box size="0.025 0.025 0.025"/></geometry>
    </visual>
    <collision>
      <origin xyz="0.0125 0 0" rpy="0 0 0"/>
      <geometry><box size="0.025 0.025 0.025"/></geometry>
    </collision>
    <inertial>
      <mass value="0.018750"/>
      <inertia ixx="1.953125e-06" iyy="1.953125e-06" izz="1.953125e-06" ixy="0" ixz="0" iyz="0"/>
    </inertial>
  </link>
  <joint name="joint_body_leg_hip_0" type="revolute">
    <parent link="body"/>
    <child link="leg_hip_0"/>
    <origin xyz="0.21875 0.0 0" rpy="0 0 0.0"/>
    <axis xyz="0 0 1"/>
    <limit lower="-0.9599310885968813" upper="0.9599310885968813" effort="12" velocity="12.0"/>
    <dynamics damping="0.2" friction="0.1"/>
  </joint>
  <link name="leg_upper_0">
    <visual>
      <origin xyz="0.0625 0 0" rpy="0 0 0"/>
      <geometry><box size="0.125 0.025 0.025"/></geometry>
    </visual>
    <collision>
      <origin xyz="0.0625 0 0" rpy="0 0 0"/>
      <geometry><box size="0.125 0.025 0.025"/></geometry>
    </collision>
    <inertial>
      <mass value="0.093750"/>
      <inertia ixx="9.765625e-06" iyy="1.269531e-04" izz="1.269531e-04" ixy="0" ixz="0" iyz="0"/>
    </inertial>
  </link>
  <joint name="joint_leg_hip_leg_upper_0" type="revolute">
    <parent link="leg_hip_0"/>
    <child link="leg_upper_0"/>
    <origin xyz="0.025 0 0" rpy="0 0 0.0"/>
    <axis xyz="0 -1 0"/>
    <limit lower="-1.3089969389957472" upper="1.3089969389957472" effort="30" velocity="15.0"/>
    <dynamics damping="0.6" friction="0.3"/>
  </joint>
  <link name="leg_middle_0">
    <visual>
      <origin xyz="0.0875 0 0" rpy="0 0 0"/>
      <geometry><box size="0.175 0.025 0.025"/></geometry>
    </visual>
    <collision>
      <origin xyz="0.0875 0 0" rpy="0 0 0"/>
      <geometry><box size="0.175 0.025 0.025"/></geometry>
    </collision>
    <inertial>
      <mass value="0.131250"/>
      <inertia ixx="1.367188e-05" iyy="3.417969e-04" izz="3.417969e-04" ixy="0" ixz="0" iyz="0"/>
    </inertial>
  </link>
  <joint name="joint_leg_upper_leg_middle_0" type="revolute">
    <parent link="leg_upper_0"/>
    <child link="leg_middle_0"/>
    <origin xyz="0.125 0 0" rpy="0 0 0.0"/>
    <axis xyz="0 -1 0"/>
    <limit lower="-1.5707963267948966" upper="0.3490658503988659" effort="22" velocity="15.0"/>
    <dynamics damping="0.4" friction="0.2"/>
  </joint>
  <link name="leg_lower_0">
    <visual>
      <origin xyz="0.0875 0 0" rpy="0 0 0"/>
      <geometry><box size="0.175 0.025 0.025"/></geometry>
    </visual>
    <collision>
      <origin xyz="0.0875 0 0" rpy="0 0 0"/>
      <geometry><box size="0.175 0.025 0.025"/></geometry>
    </collision>
    <inertial>
      <mass value="0.131250"/>
      <inertia ixx="1.367188e-05" iyy="3.417969e-04" izz="3.417969e-04" ixy="0" ixz="0" iyz="0"/>
    </inertial>
  </link>
  <joint name="joint_leg_middle_leg_lower_0" type="revolute">
    <parent link="leg_middle_0"/>
    <child link="leg_lower_0"/>
    <origin xyz="0.175 0 0" rpy="0 0 0.0"/>
    <axis xyz="0 -1 0"/>
    <limit lower="-1.5707963267948966" upper="0.7853981633974483" effort="11" velocity="15.0"/>
    <dynamics damping="0.2" friction="0.1"/>
  </joint>
  <link name="leg_foot_0">
    <visual>
      
      <geometry><sphere radius="0.01767766952966369"/></geometry>
    </visual>
    <collision>
      
      <geometry><sphere radius="0.01767766952966369"/></geometry>
    </collision>
    <inertial>
      <mass value="0.027768"/>
      <inertia ixx="3.471002e-06" iyy="3.471002e-06" izz="3.471002e-06" ixy="0" ixz="0" iyz="0"/>
    </inertial>
  </link>
  <joint name="joint_leg_lower_foot_0" type="revolute">
    <parent link="leg_lower_0"/>
    <child link="leg_foot_0"/>
    <origin xyz="0.175 0 0" rpy="0 0 0"/>
    <axis xyz="0 1 0"/>
    <limit lower="0" upper="0" effort="0" velocity="0"/>
  </joint>
  <link name="leg_hip_1">
    <visual>
      <origin xyz="0.0125 0 0" rpy="0 0 0"/>
      <geometry><box size="0.025 0.025 0.025"/></geometry>
    </visual>
    <collision>
      <origin xyz="0.0125 0 0" rpy="0 0 0"/>
      <geometry><box size="0.025 0.025 0.025"/></geometry>
    </collision>
    <inertial>
      <mass value="0.018750"/>
      <inertia ixx="1.953125e-06" iyy="1.953125e-06" izz="1.953125e-06" ixy="0" ixz="0" iyz="0"/>
    </inertial>
  </link>
  <joint name="joint_body_leg_hip_1" type="revolute">
    <parent link="body"/>
    <child link="leg_hip_1"/>
    <origin xyz="0.10937500000000003 0.18944305707784595 0" rpy="0 0 1.0471975511965976"/>
    <axis xyz="0 0 1"/>
    <limit lower="-0.9599310885968813" upper="0.9599310885968813" effort="12" velocity="12.0"/>
    <dynamics damping="0.2" friction="0.1"/>
  </joint>
  <link name="leg_upper_1">
    <visual>
      <origin xyz="0.0625 0 0" rpy="0 0 0"/>
      <geometry><box size="0.125 0.025 0.025"/></geometry>
    </visual>
    <collision>
      <origin xyz="0.0625 0 0" rpy="0 0 0"/>
      <geometry><box size="0.125 0.025 0.025"/></geometry>
    </collision>
    <inertial>
      <mass value="0.093750"/>
      <inertia ixx="9.765625e-06" iyy="1.269531e-04" izz="1.269531e-04" ixy="0" ixz="0" iyz="0"/>
    </inertial>
  </link>
  <joint name="joint_leg_hip_leg_upper_1" type="revolute">
    <parent link="leg_hip_1"/>
    <child link="leg_upper_1"/>
    <origin xyz="0.025 0 0" rpy="0 0 0.0"/>
    <axis xyz="0 -1 0"/>
    <limit lower="-1.3089969389957472" upper="1.3089969389957472" effort="30" velocity="15.0"/>
    <dynamics damping="0.6" friction="0.3"/>
  </joint>
  <link name="leg_middle_1">
    <visual>
      <origin xyz="0.0875 0 0" rpy="0 0 0"/>
      <geometry><box size="0.175 0.025 0.025"/></geometry>
    </visual>
    <collision>
      <origin xyz="0.0875 0 0" rpy="0 0 0"/>
      <geometry><box size="0.175 0.025 0.025"/></geometry>
    </collision>
    <inertial>
      <mass value="0.131250"/>
      <inertia ixx="1.367188e-05" iyy="3.417969e-04" izz="3.417969e-04" ixy="0" ixz="0" iyz="0"/>
    </inertial>
  </link>
  <joint name="joint_leg_upper_leg_middle_1" type="revolute">
    <parent link="leg_upper_1"/>
    <child link="leg_middle_1"/>
    <origin xyz="0.125 0 0" rpy="0 0 0.0"/>
    <axis xyz="0 -1 0"/>
    <limit lower="-1.5707963267948966" upper="0.3490658503988659" effort="22" velocity="15.0"/>
    <dynamics damping="0.4" friction="0.2"/>
  </joint>
  <link name="leg_lower_1">
    <visual>
      <origin xyz="0.0875 0 0" rpy="0 0 0"/>
      <geometry><box size="0.175 0.025 0.025"/></geometry>
    </visual>
    <collision>
      <origin xyz="0.0875 0 0" rpy="0 0 0"/>
      <geometry><box size="0.175 0.025 0.025"/></geometry>
    </collision>
    <inertial>
      <mass value="0.131250"/>
      <inertia ixx="1.367188e-05" iyy="3.417969e-04" izz="3.417969e-04" ixy="0" ixz="0" iyz="0"/>
    </inertial>
  </link>
  <joint name="joint_leg_middle_leg_lower_1" type="revolute">
    <parent link="leg_middle_1"/>
    <child link="leg_lower_1"/>
    <origin xyz="0.175 0 0" rpy="0 0 0.0"/>
    <axis xyz="0 -1 0"/>
    <limit lower="-1.5707963267948966" upper="0.7853981633974483" effort="11" velocity="15.0"/>
    <dynamics damping="0.2" friction="0.1"/>
  </joint>
  <link name="leg_foot_1">
    <visual>
      
      <geometry><sphere radius="0.01767766952966369"/></geometry>
    </visual>
    <collision>
      
      <geometry><sphere radius="0.01767766952966369"/></geometry>
    </collision>
    <inertial>
      <mass value="0.027768"/>
      <inertia ixx="3.471002e-06" iyy="3.471002e-06" izz="3.471002e-06" ixy="0" ixz="0" iyz="0"/>
    </inertial>
  </link>
  <joint name="joint_leg_lower_foot_1" type="revolute">
    <parent link="leg_lower_1"/>
    <child link="leg_foot_1"/>
    <origin xyz="0.175 0 0" rpy="0 0 0"/>
    <axis xyz="0 1 0"/>
    <limit lower="0" upper="0" effort="0" velocity="0"/>
  </joint>
  <link name="leg_hip_2">
    <visual>
      <origin xyz="0.0125 0 0" rpy="0 0 0"/>
      <geometry><box size="0.025 0.025 0.025"/></geometry>
    </visual>
    <collision>
      <origin xyz="0.0125 0 0" rpy="0 0 0"/>
      <geometry><box size="0.025 0.025 0.025"/></geometry>
    </collision>
    <inertial>
      <mass value="0.018750"/>
      <inertia ixx="1.953125e-06" iyy="1.953125e-06" izz="1.953125e-06" ixy="0" ixz="0" iyz="0"/>
    </inertial>
  </link>
  <joint name="joint_body_leg_hip_2" type="revolute">
    <parent link="body"/>
    <child link="leg_hip_2"/>
    <origin xyz="-0.10937499999999994 0.18944305707784598 0" rpy="0 0 2.0943951023931953"/>
    <axis xyz="0 0 1"/>
    <limit lower="-0.9599310885968813" upper="0.9599310885968813" effort="12" velocity="12.0"/>
    <dynamics damping="0.2" friction="0.1"/>
  </joint>
  <link name="leg_upper_2">
    <visual>
      <origin xyz="0.0625 0 0" rpy="0 0 0"/>
      <geometry><box size="0.125 0.025 0.025"/></geometry>
    </visual>
    <collision>
      <origin xyz="0.0625 0 0" rpy="0 0 0"/>
      <geometry><box size="0.125 0.025 0.025"/></geometry>
    </collision>
    <inertial>
      <mass value="0.093750"/>
      <inertia ixx="9.765625e-06" iyy="1.269531e-04" izz="1.269531e-04" ixy="0" ixz="0" iyz="0"/>
    </inertial>
  </link>
  <joint name="joint_leg_hip_leg_upper_2" type="revolute">
    <parent link="leg_hip_2"/>
    <child link="leg_upper_2"/>
    <origin xyz="0.025 0 0" rpy="0 0 0.0"/>
    <axis xyz="0 -1 0"/>
    <limit lower="-1.3089969389957472" upper="1.3089969389957472" effort="30" velocity="15.0"/>
    <dynamics damping="0.6" friction="0.3"/>
  </joint>
  <link name="leg_middle_2">
    <visual>
      <origin xyz="0.0875 0 0" rpy="0 0 0"/>
      <geometry><box size="0.175 0.025 0.025"/></geometry>
    </visual>
    <collision>
      <origin xyz="0.0875 0 0" rpy="0 0 0"/>
      <geometry><box size="0.175 0.025 0.025"/></geometry>
    </collision>
    <inertial>
      <mass value="0.131250"/>
      <inertia ixx="1.367188e-05" iyy="3.417969e-04" izz="3.417969e-04" ixy="0" ixz="0" iyz="0"/>
    </inertial>
  </link>
  <joint name="joint_leg_upper_leg_middle_2" type="revolute">
    <parent link="leg_upper_2"/>
    <child link="leg_middle_2"/>
    <origin xyz="0.125 0 0" rpy="0 0 0.0"/>
    <axis xyz="0 -1 0"/>
    <limit lower="-1.5707963267948966" upper="0.3490658503988659" effort="22" velocity="15.0"/>
    <dynamics damping="0.4" friction="0.2"/>
  </joint>
  <link name="leg_lower_2">
    <visual>
      <origin xyz="0.0875 0 0" rpy="0 0 0"/>
      <geometry><box size="0.175 0.025 0.025"/></geometry>
    </visual>
    <collision>
      <origin xyz="0.0875 0 0" rpy="0 0 0"/>
      <geometry><box size="0.175 0.025 0.025"/></geometry>
    </collision>
    <inertial>
      <mass value="0.131250"/>
      <inertia ixx="1.367188e-05" iyy="3.417969e-04" izz="3.417969e-04" ixy="0" ixz="0" iyz="0"/>
    </inertial>
  </link>
  <joint name="joint_leg_middle_leg_lower_2" type="revolute">
    <parent link="leg_middle_2"/>
    <child link="leg_lower_2"/>
    <origin xyz="0.175 0 0" rpy="0 0 0.0"/>
    <axis xyz="0 -1 0"/>
    <limit lower="-1.5707963267948966" upper="0.7853981633974483" effort="11" velocity="15.0"/>
    <dynamics damping="0.2" friction="0.1"/>
  </joint>
  <link name="leg_foot_2">
    <visual>
      
      <geometry><sphere radius="0.01767766952966369"/></geometry>
    </visual>
    <collision>
      
      <geometry><sphere radius="0.01767766952966369"/></geometry>
    </collision>
    <inertial>
      <mass value="0.027768"/>
      <inertia ixx="3.471002e-06" iyy="3.471002e-06" izz="3.471002e-06" ixy="0" ixz="0" iyz="0"/>
    </inertial>
  </link>
  <joint name="joint_leg_lower_foot_2" type="revolute">
    <parent link="leg_lower_2"/>
    <child link="leg_foot_2"/>
    <origin xyz="0.175 0 0" rpy="0 0 0"/>
    <axis xyz="0 1 0"/>
    <limit lower="0" upper="0" effort="0" velocity="0"/>
  </joint>
  <link name="leg_hip_3">
    <visual>
      <origin xyz="0.0125 0 0" rpy="0 0 0"/>
      <geometry><box size="0.025 0.025 0.025"/></geometry>
    </visual>
    <collision>
      <origin xyz="0.0125 0 0" rpy="0 0 0"/>
      <geometry><box size="0.025 0.025 0.025"/></geometry>
    </collision>
    <inertial>
      <mass value="0.018750"/>
      <inertia ixx="1.953125e-06" iyy="1.953125e-06" izz="1.953125e-06" ixy="0" ixz="0" iyz="0"/>
    </inertial>
  </link>
  <joint name="joint_body_leg_hip_3" type="revolute">
    <parent link="body"/>
    <child link="leg_hip_3"/>
    <origin xyz="-0.21875 2.678914873134835e-17 0" rpy="0 0 3.141592653589793"/>
    <axis xyz="0 0 1"/>
    <limit lower="-0.9599310885968813" upper="0.9599310885968813" effort="12" velocity="12.0"/>
    <dynamics damping="0.2" friction="0.1"/>
  </joint>
  <link name="leg_upper_3">
    <visual>
      <origin xyz="0.0625 0 0" rpy="0 0 0"/>
      <geometry><box size="0.125 0.025 0.025"/></geometry>
    </visual>
    <collision>
      <origin xyz="0.0625 0 0" rpy="0 0 0"/>
      <geometry><box size="0.125 0.025 0.025"/></geometry>
    </collision>
    <inertial>
      <mass value="0.093750"/>
      <inertia ixx="9.765625e-06" iyy="1.269531e-04" izz="1.269531e-04" ixy="0" ixz="0" iyz="0"/>
    </inertial>
  </link>
  <joint name="joint_leg_hip_leg_upper_3" type="revolute">
    <parent link="leg_hip_3"/>
    <child link="leg_upper_3"/>
    <origin xyz="0.025 0 0" rpy="0 0 0.0"/>
    <axis xyz="0 -1 0"/>
    <limit lower="-1.3089969389957472" upper="1.3089969389957472" effort="30" velocity="15.0"/>
    <dynamics damping="0.6" friction="0.3"/>
  </joint>
  <link name="leg_middle_3">
    <visual>
      <origin xyz="0.0875 0 0" rpy="0 0 0"/>
      <geometry><box size="0.175 0.025 0.025"/></geometry>
    </visual>
    <collision>
      <origin xyz="0.0875 0 0" rpy="0 0 0"/>
      <geometry><box size="0.175 0.025 0.025"/></geometry>
    </collision>
    <inertial>
      <mass value="0.131250"/>
      <inertia ixx="1.367188e-05" iyy="3.417969e-04" izz="3.417969e-04" ixy="0" ixz="0" iyz="0"/>
    </inertial>
  </link>
  <joint name="joint_leg_upper_leg_middle_3" type="revolute">
    <parent link="leg_upper_3"/>
    <child link="leg_middle_3"/>
    <origin xyz="0.125 0 0" rpy="0 0 0.0"/>
    <axis xyz="0 -1 0"/>
    <limit lower="-1.5707963267948966" upper="0.3490658503988659" effort="22" velocity="15.0"/>
    <dynamics damping="0.4" friction="0.2"/>
  </joint>
  <link name="leg_lower_3">
    <visual>
      <origin xyz="0.0875 0 0" rpy="0 0 0"/>
      <geometry><box size="0.175 0.025 0.025"/></geometry>
    </visual>
    <collision>
      <origin xyz="0.0875 0 0" rpy="0 0 0"/>
      <geometry><box size="0.175 0.025 0.025"/></geometry>
    </collision>
    <inertial>
      <mass value="0.131250"/>
      <inertia ixx="1.367188e-05" iyy="3.417969e-04" izz="3.417969e-04" ixy="0" ixz="0" iyz="0"/>
    </inertial>
  </link>
  <joint name="joint_leg_middle_leg_lower_3" type="revolute">
    <parent link="leg_middle_3"/>
    <child link="leg_lower_3"/>
    <origin xyz="0.175 0 0" rpy="0 0 0.0"/>
    <axis xyz="0 -1 0"/>
    <limit lower="-1.5707963267948966" upper="0.7853981633974483" effort="11" velocity="15.0"/>
    <dynamics damping="0.2" friction="0.1"/>
  </joint>
  <link name="leg_foot_3">
    <visual>
      
      <geometry><sphere radius="0.01767766952966369"/></geometry>
    </visual>
    <collision>
      
      <geometry><sphere radius="0.01767766952966369"/></geometry>
    </collision>
    <inertial>
      <mass value="0.027768"/>
      <inertia ixx="3.471002e-06" iyy="3.471002e-06" izz="3.471002e-06" ixy="0" ixz="0" iyz="0"/>
    </inertial>
  </link>
  <joint name="joint_leg_lower_foot_3" type="revolute">
    <parent link="leg_lower_3"/>
    <child link="leg_foot_3"/>
    <origin xyz="0.175 0 0" rpy="0 0 0"/>
    <axis xyz="0 1 0"/>
    <limit lower="0" upper="0" effort="0" velocity="0"/>
  </joint>
  <link name="leg_hip_4">
    <visual>
      <origin xyz="0.0125 0 0" rpy="0 0 0"/>
      <geometry><box size="0.025 0.025 0.025"/></geometry>
    </visual>
    <collision>
      <origin xyz="0.0125 0 0" rpy="0 0 0"/>
      <geometry><box size="0.025 0.025 0.025"/></geometry>
    </collision>
    <inertial>
      <mass value="0.018750"/>
      <inertia ixx="1.953125e-06" iyy="1.953125e-06" izz="1.953125e-06" ixy="0" ixz="0" iyz="0"/>
    </inertial>
  </link>
  <joint name="joint_body_leg_hip_4" type="revolute">
    <parent link="body"/>
    <child link="leg_hip_4"/>
    <origin xyz="-0.1093750000000001 -0.18944305707784592 0" rpy="0 0 4.1887902047863905"/>
    <axis xyz="0 0 1"/>
    <limit lower="-0.9599310885968813" upper="0.9599310885968813" effort="12" velocity="12.0"/>
    <dynamics damping="0.2" friction="0.1"/>
  </joint>
  <link name="leg_upper_4">
    <visual>
      <origin xyz="0.0625 0 0" rpy="0 0 0"/>
      <geometry><box size="0.125 0.025 0.025"/></geometry>
    </visual>
    <collision>
      <origin xyz="0.0625 0 0" rpy="0 0 0"/>
      <geometry><box size="0.125 0.025 0.025"/></geometry>
    </collision>
    <inertial>
      <mass value="0.093750"/>
      <inertia ixx="9.765625e-06" iyy="1.269531e-04" izz="1.269531e-04" ixy="0" ixz="0" iyz="0"/>
    </inertial>
  </link>
  <joint name="joint_leg_hip_leg_upper_4" type="revolute">
    <parent link="leg_hip_4"/>
    <child link="leg_upper_4"/>
    <origin xyz="0.025 0 0" rpy="0 0 0.0"/>
    <axis xyz="0 -1 0"/>
    <limit lower="-1.3089969389957472" upper="1.3089969389957472" effort="30" velocity="15.0"/>
    <dynamics damping="0.6" friction="0.3"/>
  </joint>
  <link name="leg_middle_4">
    <visual>
      <origin xyz="0.0875 0 0" rpy="0 0 0"/>
      <geometry><box size="0.175 0.025 0.025"/></geometry>
    </visual>
    <collision>
      <origin xyz="0.0875 0 0" rpy="0 0 0"/>
      <geometry><box size="0.175 0.025 0.025"/></geometry>
    </collision>
    <inertial>
      <mass value="0.131250"/>
      <inertia ixx="1.367188e-05" iyy="3.417969e-04" izz="3.417969e-04" ixy="0" ixz="0" iyz="0"/>
    </inertial>
  </link>
  <joint name="joint_leg_upper_leg_middle_4" type="revolute">
    <parent link="leg_upper_4"/>
    <child link="leg_middle_4"/>
    <origin xyz="0.125 0 0" rpy="0 0 0.0"/>
    <axis xyz="0 -1 0"/>
    <limit lower="-1.5707963267948966" upper="0.3490658503988659" effort="22" velocity="15.0"/>
    <dynamics damping="0.4" friction="0.2"/>
  </joint>
  <link name="leg_lower_4">
    <visual>
      <origin xyz="0.0875 0 0" rpy="0 0 0"/>
      <geometry><box size="0.175 0.025 0.025"/></geometry>
    </visual>
    <collision>
      <origin xyz="0.0875 0 0" rpy="0 0 0"/>
      <geometry><box size="0.175 0.025 0.025"/></geometry>
    </collision>
    <inertial>
      <mass value="0.131250"/>
      <inertia ixx="1.367188e-05" iyy="3.417969e-04" izz="3.417969e-04" ixy="0" ixz="0" iyz="0"/>
    </inertial>
  </link>
  <joint name="joint_leg_middle_leg_lower_4" type="revolute">
    <parent link="leg_middle_4"/>
    <child link="leg_lower_4"/>
    <origin xyz="0.175 0 0" rpy="0 0 0.0"/>
    <axis xyz="0 -1 0"/>
    <limit lower="-1.5707963267948966" upper="0.7853981633974483" effort="11" velocity="15.0"/>
    <dynamics damping="0.2" friction="0.1"/>
  </joint>
  <link name="leg_foot_4">
    <visual>
      
      <geometry><sphere radius="0.01767766952966369"/></geometry>
    </visual>
    <collision>
      
      <geometry><sphere radius="0.01767766952966369"/></geometry>
    </collision>
    <inertial>
      <mass value="0.027768"/>
      <inertia ixx="3.471002e-06" iyy="3.471002e-06" izz="3.471002e-06" ixy="0" ixz="0" iyz="0"/>
    </inertial>
  </link>
  <joint name="joint_leg_lower_foot_4" type="revolute">
    <parent link="leg_lower_4"/>
    <child link="leg_foot_4"/>
    <origin xyz="0.175 0 0" rpy="0 0 0"/>
    <axis xyz="0 1 0"/>
    <limit lower="0" upper="0" effort="0" velocity="0"/>
  </joint>
  <link name="leg_hip_5">
    <visual>
      <origin xyz="0.0125 0 0" rpy="0 0 0"/>
      <geometry><box size="0.025 0.025 0.025"/></geometry>
    </visual>
    <collision>
      <origin xyz="0.0125 0 0" rpy="0 0 0"/>
      <geometry><box size="0.025 0.025 0.025"/></geometry>
    </collision>
    <inertial>
      <mass value="0.018750"/>
      <inertia ixx="1.953125e-06" iyy="1.953125e-06" izz="1.953125e-06" ixy="0" ixz="0" iyz="0"/>
    </inertial>
  </link>
  <joint name="joint_body_leg_hip_5" type="revolute">
    <parent link="body"/>
    <child link="leg_hip_5"/>
    <origin xyz="0.10937499999999986 -0.18944305707784603 0" rpy="0 0 5.235987755982988"/>
    <axis xyz="0 0 1"/>
    <limit lower="-0.9599310885968813" upper="0.9599310885968813" effort="12" velocity="12.0"/>
    <dynamics damping="0.2" friction="0.1"/>
  </joint>
  <link name="leg_upper_5">
    <visual>
      <origin xyz="0.0625 0 0" rpy="0 0 0"/>
      <geometry><box size="0.125 0.025 0.025"/></geometry>
    </visual>
    <collision>
      <origin xyz="0.0625 0 0" rpy="0 0 0"/>
      <geometry><box size="0.125 0.025 0.025"/></geometry>
    </collision>
    <inertial>
      <mass value="0.093750"/>
      <inertia ixx="9.765625e-06" iyy="1.269531e-04" izz="1.269531e-04" ixy="0" ixz="0" iyz="0"/>
    </inertial>
  </link>
  <joint name="joint_leg_hip_leg_upper_5" type="revolute">
    <parent link="leg_hip_5"/>
    <child link="leg_upper_5"/>
    <origin xyz="0.025 0 0" rpy="0 0 0.0"/>
    <axis xyz="0 -1 0"/>
    <limit lower="-1.3089969389957472" upper="1.3089969389957472" effort="30" velocity="15.0"/>
    <dynamics damping="0.6" friction="0.3"/>
  </joint>
  <link name="leg_middle_5">
    <visual>
      <origin xyz="0.0875 0 0" rpy="0 0 0"/>
      <geometry><box size="0.175 0.025 0.025"/></geometry>
    </visual>
    <collision>
      <origin xyz="0.0875 0 0" rpy="0 0 0"/>
      <geometry><box size="0.175 0.025 0.025"/></geometry>
    </collision>
    <inertial>
      <mass value="0.131250"/>
      <inertia ixx="1.367188e-05" iyy="3.417969e-04" izz="3.417969e-04" ixy="0" ixz="0" iyz="0"/>
    </inertial>
  </link>
  <joint name="joint_leg_upper_leg_middle_5" type="revolute">
    <parent link="leg_upper_5"/>
    <child link="leg_middle_5"/>
    <origin xyz="0.125 0 0" rpy="0 0 0.0"/>
    <axis xyz="0 -1 0"/>
    <limit lower="-1.5707963267948966" upper="0.3490658503988659" effort="22" velocity="15.0"/>
    <dynamics damping="0.4" friction="0.2"/>
  </joint>
  <link name="leg_lower_5">
    <visual>
      <origin xyz="0.0875 0 0" rpy="0 0 0"/>
      <geometry><box size="0.175 0.025 0.025"/></geometry>
    </visual>
    <collision>
      <origin xyz="0.0875 0 0" rpy="0 0 0"/>
      <geometry><box size="0.175 0.025 0.025"/></geometry>
    </collision>
    <inertial>
      <mass value="0.131250"/>
      <inertia ixx="1.367188e-05" iyy="3.417969e-04" izz="3.417969e-04" ixy="0" ixz="0" iyz="0"/>
    </inertial>
  </link>
  <joint name="joint_leg_middle_leg_lower_5" type="revolute">
    <parent link="leg_middle_5"/>
    <child link="leg_lower_5"/>
    <origin xyz="0.175 0 0" rpy="0 0 0.0"/>
    <axis xyz="0 -1 0"/>
    <limit lower="-1.5707963267948966" upper="0.7853981633974483" effort="11" velocity="15.0"/>
    <dynamics damping="0.2" friction="0.1"/>
  </joint>
  <link name="leg_foot_5">
    <visual>
      
      <geometry><sphere radius="0.01767766952966369"/></geometry>
    </visual>
    <collision>
      
      <geometry><sphere radius="0.01767766952966369"/></geometry>
    </collision>
    <inertial>
      <mass value="0.027768"/>
      <inertia ixx="3.471002e-06" iyy="3.471002e-06" izz="3.471002e-06" ixy="0" ixz="0" iyz="0"/>
    </inertial>
  </link>
  <joint name="joint_leg_lower_foot_5" type="revolute">
    <parent link="leg_lower_5"/>
    <child link="leg_foot_5"/>
    <origin xyz="0.175 0 0" rpy="0 0 0"/>
    <axis xyz="0 1 0"/>
    <limit lower="0" upper="0" effort="0" velocity="0"/>
  </joint>
</robot>
